<robot name="onshape">
<link name="l0">
<visual>
<origin xyz="0 0 0" rpy="3.141592653589793116 -0 -2.5276961678383067331e-30" />
<geometry>
<mesh filename="package:///l0.stl"/>
</geometry>
<material name="l0_material">
<color rgba="0.30196078431372547213 0.30196078431372547213 0.30196078431372547213 1.0"/>
</material>
</visual>
<collision>
<origin xyz="0 0 0" rpy="3.141592653589793116 -0 -2.5276961678383067331e-30" />
<geometry>
<mesh filename="package:///l0.stl"/>
</geometry>
</collision>
<inertial>
<origin xyz="-1.0447250926720843811e-17 9.5117965647274377008e-18 0.050000000000000009714" rpy="0 0 0"/>
<mass value="31.011862534247164547" />
<inertia ixx="0.12702564380794917342" ixy="-6.4216446614109371414e-31"  ixz="0" iyy="0.12702564380794917342" iyz="0" izz="0.20236485005881971189" />
</inertial>
</link>

<link name="l1">
<visual>
<origin xyz="1.2037062152420224082e-35 4.5924254968025751432e-18 0.10000000000000001943" rpy="1.0321828577466960649e-33 -9.6215524705802266045e-35 6.2250777877005559414e-21" />
<geometry>
<mesh filename="package:///l1.stl"/>
</geometry>
<material name="l1_material">
<color rgba="0.30196078431372547213 0.30196078431372547213 0.30196078431372547213 1.0"/>
</material>
</visual>
<collision>
<origin xyz="1.2037062152420224082e-35 4.5924254968025751432e-18 0.10000000000000001943" rpy="1.0321828577466960649e-33 -9.6215524705802266045e-35 6.2250777877005559414e-21" />
<geometry>
<mesh filename="package:///l1.stl"/>
</geometry>
</collision>
<inertial>
<origin xyz="-4.5582807839372038651e-19 -1.8971629052710362283e-07 -0.048596791911239126116" rpy="0 0 0"/>
<mass value="13.447711806464676343" />
<inertia ixx="0.0291513167692083984" ixy="-1.0829113272749959726e-20"  ixz="5.1942187722507397852e-26" iyy="0.029151283995942408461" iyz="-1.3752055963645271433e-07" izz="0.036931024403735940309" />
</inertial>
</link>

<link name="l2">
<visual>
<origin xyz="8.3266726846886740532e-17 -0.55000000000000004441 -0.012500000000000000694" rpy="1.570796326794896558 -5.1724305203831434374e-20 -1.0189144506468097477e-16" />
<geometry>
<mesh filename="package:///l2.stl"/>
</geometry>
<material name="l2_material">
<color rgba="0.30196078431372547213 0.30196078431372547213 0.30196078431372547213 1.0"/>
</material>
</visual>
<collision>
<origin xyz="8.3266726846886740532e-17 -0.55000000000000004441 -0.012500000000000000694" rpy="1.570796326794896558 -5.1724305203831434374e-20 -1.0189144506468097477e-16" />
<geometry>
<mesh filename="package:///l2.stl"/>
</geometry>
</collision>
<inertial>
<origin xyz="-3.5484387926505917231e-17 -0.17500000000000004441 -0.012500000000000000694" rpy="0 0 0"/>
<mass value="3.3373406335618427399" />
<inertia ixx="0.03243869811840714712" ixy="-3.3024160208855979611e-18"  ixz="3.0414767066813749705e-21" iyy="0.00084992367319783681829" iyz="-9.4436144041212276428e-21" izz="0.032940982142275622435" />
</inertial>
</link>

<link name="l3">
<visual>
<origin xyz="5.5511151231257827021e-17 1 -0.012500000000000000694" rpy="-1.570796326794896558 4.2673035708211722495e-19 -3.432014645827615996e-17" />
<geometry>
<mesh filename="package:///l3.stl"/>
</geometry>
<material name="l3_material">
<color rgba="0.30196078431372547213 0.30196078431372547213 0.30196078431372547213 1.0"/>
</material>
</visual>
<collision>
<origin xyz="5.5511151231257827021e-17 1 -0.012500000000000000694" rpy="-1.570796326794896558 4.2673035708211722495e-19 -3.432014645827615996e-17" />
<geometry>
<mesh filename="package:///l3.stl"/>
</geometry>
</collision>
<inertial>
<origin xyz="-2.3670997870391349713e-17 0.22499999999999986677 -0.012500000000000002429" rpy="0 0 0"/>
<mass value="4.3185906335617918472" />
<inertia ixx="0.070055563123260805591" ixy="-2.392829986150813878e-18"  ixz="1.4828870041893290494e-21" iyy="0.0011054575273644713304" iyz="-7.7586356947486391837e-21" izz="0.070711167459629256649" />
</inertial>
</link>

<link name="l4">
<visual>
<origin xyz="-2.1807552291752685392e-11 0.99750766000056456662 -0.0010000000000000286438" rpy="-1.570796326794896558 -4.3319304112443071588e-19 3.4784418374339715384e-18" />
<geometry>
<mesh filename="package:///l4.stl"/>
</geometry>
<material name="l4_material">
<color rgba="0.30196078431372547213 0.30196078431372547213 0.30196078431372547213 1.0"/>
</material>
</visual>
<collision>
<origin xyz="-2.1807552291752685392e-11 0.99750766000056456662 -0.0010000000000000286438" rpy="-1.570796326794896558 -4.3319304112443071588e-19 3.4784418374339715384e-18" />
<geometry>
<mesh filename="package:///l4.stl"/>
</geometry>
</collision>
<inertial>
<origin xyz="-2.2331052875503100188e-11 -0.052484409044063699834 -0.00099992443137562848562" rpy="0 0 0"/>
<mass value="1.3020665219465743512" />
<inertia ixx="0.0010034701633462978724" ixy="2.7388691651503683504e-14"  ixz="3.9050200709573549733e-15" iyy="0.00037588717720715621737" iyz="-5.1639913656488564488e-09" izz="0.0010034705085381321905" />
</inertial>
</link>

<link name="l5">
<visual>
<origin xyz="0 -6.0715321659188248304e-18 1.1000000000000000888" rpy="-6.7675646455164446705e-19 -2.8700942116727793454e-17 3.4890692579606588748e-17" />
<geometry>
<mesh filename="package:///l5.stl"/>
</geometry>
<material name="l5_material">
<color rgba="0.59607843137254901134 0.17647058823529412908 0.050980392156862744391 1.0"/>
</material>
</visual>
<collision>
<origin xyz="0 -6.0715321659188248304e-18 1.1000000000000000888" rpy="-6.7675646455164446705e-19 -2.8700942116727793454e-17 3.4890692579606588748e-17" />
<geometry>
<mesh filename="package:///l5.stl"/>
</geometry>
</collision>
<inertial>
<origin xyz="-2.5141564181677030927e-17 1.6194567908339470688e-17 -0.08170186777205912243" rpy="0 0 0"/>
<mass value="2.8350584440449333457" />
<inertia ixx="0.0051009846599758320446" ixy="1.860653935360966628e-19"  ixz="1.3109382123381862934e-19" iyy="0.010187900103340868582" iyz="-1.08253711889729129e-19" izz="0.0052078779369776201369" />
</inertial>
</link>

<joint name="j4_continuous" type="revolute">
<origin xyz="-2.1807555761199637345e-11 -0.10249233999943557771 -0.0010000000000001119105" rpy="1.5707963267948974462 -1.4415324059003871149 3.1415926535897611416" />
<parent link="l4" />
<child link="l5" />
<axis xyz="0 0 1"/>
<limit effort="1" velocity="20" />
<joint_properties friction="0.0"/>
</joint>

<joint name="j3_continuous" type="revolute">
<origin xyz="-5.5511151231257827021e-17 0.45000000000000006661 -0.012500000000000004163" rpy="-1.570796326794896558 1.5440601655300412176 3.1415926535897193972" />
<parent link="l3" />
<child link="l4" />
<axis xyz="0 0 1"/>
<limit effort="1" velocity="20" />
<joint_properties friction="0.0"/>
</joint>

<joint name="j2" type="revolute">
<origin xyz="-1.9428902930940239457e-16 -0.35000000000000330846 -0.025000000000000015266" rpy="-3.1415926535897904515 3.4189179422415795443e-16 1.9872695389451910941" />
<parent link="l2" />
<child link="l3" />
<axis xyz="0 0 1"/>
<limit effort="1" velocity="20" />
<joint_properties friction="0.0"/>
</joint>

<joint name="j1" type="revolute">
<origin xyz="3.4208452816061431113e-16 -0.012499999999999997224 -0.10250000000000034084" rpy="1.57079632679489678 -0.65183928279709479892 -1.7774619825444202965e-15" />
<parent link="l1" />
<child link="l2" />
<axis xyz="0 0 1"/>
<limit effort="1" velocity="20" lower="1.0471975511965976313" upper="5.2359877559829888227"/>
<joint_properties friction="0.0"/>
</joint>

<joint name="j0_continuous" type="revolute">
<origin xyz="4.4433313139149082721e-20 -2.9354910603076127659e-18 0.10000000000000001943" rpy="-3.141592653589793116 1.0118004717258600843e-18 -0.0024120916050152920937" />
<parent link="l0" />
<child link="l1" />
<axis xyz="0 0 1"/>
<limit effort="1" velocity="20" />
<joint_properties friction="0.0"/>
</joint>


</robot>
